<?xml version='1.0'?>

<robot name="my_robot" xmlns:xacro="http://www.ros.org/wiki/xacro">
<xacro:include filename="$(find my_robot)/urdf/my_robot.gazebo" />
  <link name="robot_footprint"></link>

  <joint name="robot_footprint_joint" type="fixed">
    <origin xyz="0 0 0" rpy="0 0 0" />
    <parent link="robot_footprint"/>
    <child link="chassis" />
  </joint>

  <link name='chassis'>
    <pose>0 0 0.1 0 0 0</pose>

    <inertial>
      <mass value="60.0"/>
      <origin xyz="0.0 0 0" rpy=" 0 0 0"/>
      <inertia
          ixx="0.1" ixy="0" ixz="0"
          iyy="0.1" iyz="0"
          izz="0.1"
      />
    </inertial>

    <collision name='collision'>
      <origin xyz="0 0 0" rpy=" 0 0 0"/> 
      <geometry>
        <box size=".8 .4 .1"/>
      </geometry>
    </collision>

    

    <visual name='chassis_visual'>
      <origin xyz="0 0 0" rpy=" 0 0 0"/>
      <geometry>
        <box size=".8 .4 .1"/>
      </geometry>
    </visual>

  <!--.............................back_caster..............................--> 
    <collision name='back_caster_collision'>
      <origin xyz="-0.15 0 -0.05" rpy=" 0 0 0"/>
      <geometry>
        <sphere radius="0.04449"/>
      </geometry>
    </collision>

    <visual name='back_caster_visual'>
      <origin xyz="-0.15 0 -0.05" rpy=" 0 0 0"/>
      <geometry>
        <sphere radius="0.045"/>
      </geometry>
    </visual>




  <!--.............................front_caster..............................--> 
    <collision name='front_caster_collision'>
      <origin xyz="0.15 0 -0.05" rpy=" 0 0 0"/>
      <geometry>
        <sphere radius="0.0449"/>
      </geometry>
    </collision>

    <visual name='front_caster_visual'>
      <origin xyz="0.15 0 -0.05" rpy=" 0 0 0"/>
      <geometry>
        <sphere radius="0.045"/>
      </geometry>
    </visual>

  </link>

  <gazebo reference="chassis">
          <material>Gazebo/Yellow</material>
  </gazebo>


  
<!--.............................left_front_wheel..............................-->


  <link name='left_front_wheel'>
  

    <inertial>
      <mass value="5"/>
      <origin xyz="0.0 0 0" rpy=" 0 1.5707 1.5707"/>
      <inertia
          ixx="0.1" ixy="0" ixz="0"
          iyy="0.1" iyz="0"
          izz="0.1"
      />
    </inertial>


    <collision name='left_front_wheel_collision'>
      <origin xyz="0.0 0 0" rpy=" 0 1.5707 1.5707"/> 
      <geometry>
        <cylinder radius=" .12" length="0.07"/>
      </geometry>
    </collision>

    <visual name='left_front_wheel_visual'>
      <origin xyz="0.0 0 0" rpy=" 0 1.5707 1.5707"/>
      <geometry>
        <cylinder radius=" .12" length="0.07"/>
      </geometry>
    </visual>


  </link>

  <gazebo reference="left_front_wheel">
           <material>Gazebo/Blue</material>
  </gazebo>


  <joint type="continuous" name="left_front_wheel_hinge">
    <origin xyz="0.2 0.25 0" rpy="0 0 0"/>
    <child link="left_front_wheel"/>
    <parent link="chassis"/>
    <axis xyz="0 1 0" rpy="0 0 0"/>
    <limit effort="10000" velocity="1000"/>
    <dynamics damping="1.0" friction="1.0"/>
  </joint>

  


<!--.............................right_front_wheel..............................-->      
  <link name='right_front_wheel'>
    

    <inertial>
      <mass value="5"/>
      <origin xyz="0.0 0 0" rpy=" 0 1.5707 1.5707"/>
      <inertia
          ixx="0.1" ixy="0" ixz="0"
          iyy="0.1" iyz="0"
          izz="0.1"
      />
    </inertial>

    <collision name='right_front_wheel_collision'>
     <origin xyz="0.0 0 0" rpy=" 0 1.5707 1.5707"/>
      <geometry>
        <cylinder radius=" .12" length="0.07"/>
      </geometry>
    </collision>

    <visual name='right_front_wheel_visual'>
      <origin xyz="0.0 0 0" rpy=" 0 1.5707 1.5707"/>
      <geometry>
        <cylinder radius=" .12" length="0.07"/>
      </geometry>
    </visual>

  </link>

  <gazebo reference="right_front_wheel">
          <material>Gazebo/Blue</material>
  </gazebo>

  <joint type="continuous" name="right_front_wheel_hinge">
    <origin xyz="0.2 -0.25 0" rpy="0 0 0"/>
    <child link="right_front_wheel"/>
    <parent link="chassis"/>
    <axis xyz="0 1 0" rpy="0 0 0"/>
    <limit effort="10000" velocity="1000"/>
    <dynamics damping="1.0" friction="1.0"/>
  </joint>

<!--.............................left_back_wheel..............................-->


  <link name='left_back_wheel'>
  

    <inertial>
      <mass value="5"/>
      <origin xyz="0.0 0 0" rpy=" 0 1.5707 1.5707"/>
      <inertia
          ixx="0.1" ixy="0" ixz="0"
          iyy="0.1" iyz="0"
          izz="0.1"
      />
    </inertial>


    <collision name='left_back_wheel_collision'>
      <origin xyz="0.0 0 0" rpy=" 0 1.5707 1.5707"/> 
      <geometry>
        <cylinder radius=" .12" length="0.07"/>
      </geometry>
    </collision>

    <visual name='left_back_wheel_visual'>
      <origin xyz="0.0 0 0" rpy=" 0 1.5707 1.5707"/>
      <geometry>
        <cylinder radius=" .12" length="0.07"/>
      </geometry>
    </visual>


  </link>

  <gazebo reference="left_back_wheel">
          <material>Gazebo/Blue</material>
  </gazebo>


  <joint type="continuous" name="left_back_wheel_hinge">
    <origin xyz="-0.2 0.25 0" rpy="0 0 0"/>
    <child link="left_back_wheel"/>
    <parent link="chassis"/>
    <axis xyz="0 1 0" rpy="0 0 0"/>
    <limit effort="10000" velocity="1000"/>
    <dynamics damping="1.0" friction="1.1"/>
  </joint>

  


<!--.............................right_back_wheel..............................-->      
  <link name='right_back_wheel'>
    

    <inertial>
      <mass value="5"/>
      <origin xyz="0.0 0 0" rpy=" 0 1.5707 1.5707"/>
      <inertia
          ixx="0.1" ixy="0" ixz="0"
          iyy="0.1" iyz="0"
          izz="0.1"
      />
    </inertial>

    <collision name='right_back_wheel_collision'>
     <origin xyz="0.0 0 0" rpy=" 0 1.5707 1.5707"/>
      <geometry>
        <cylinder radius=" .12" length="0.07"/>
      </geometry>
    </collision>

    <visual name='right_back_wheel_visual'>
      <origin xyz="0.0 0 0" rpy=" 0 1.5707 1.5707"/>
      <geometry>
        <cylinder radius=" .12" length="0.07"/>
      </geometry>
    </visual>

  </link>

  <gazebo reference="right_back_wheel">
          <material>Gazebo/Blue</material>
  </gazebo>

  <joint type="continuous" name="right_back_wheel_hinge">
    <origin xyz="-0.2 -0.25 0" rpy="0 0 0"/>
    <child link="right_back_wheel"/>
    <parent link="chassis"/>
    <axis xyz="0 1 0" rpy="0 0 0"/>
    <limit effort="10000" velocity="1000"/>
    <dynamics damping="1.0" friction="1.1"/>
  </joint>

<!--.........Camera....................Camera................Camera..............--> 
  <link name='camera'>
    

    <inertial>
      <mass value="0.1"/>
      <origin xyz="0 0 0" rpy=" 0 0 0"/>
      <box_inertia m="0.1"/>
      <inertia
          ixx="1e-6" ixy="0" ixz="0"
          iyy="1e-6" iyz="0"
          izz="1e-6"
      />
    </inertial>

    <collision name='Camera_collision'>
     <origin xyz="0.0 0 0" rpy=" 0 0 0"/>
      <geometry>
        <box size=".05 .05 .05"/>
      </geometry>
    </collision>

    <visual name='Camera_visual'>
      <origin xyz="0.0 0 0" rpy=" 0 0 0"/>
      <geometry>
        <box size=".05 .05 .05"/>
        
      </geometry>
    </visual>

  </link>

  



  <joint type="fixed" name="camera_joint">
    <origin xyz="0.4 0 0" rpy="0 0 0"/>
    <child link="camera"/>
    <parent link="chassis"/>
    <axis xyz="0 1 0" rpy="0 0 0"/>
    <limit effort="10000" velocity="1000"/>
    <dynamics damping="1.0" friction="1.0"/>
  </joint>

  


<!--.........hokuyo....................hokuyo................hokuyo..............--> 
  <link name='hokuyo'>
    

    <inertial>
      <mass value="1e-5"/>
      <origin xyz="0 0 0" rpy=" 0 0 0"/>
      <inertia
          ixx="1e-6" ixy="0" ixz="0"
          iyy="1e-6" iyz="0"
          izz="1e-6"
      />
    </inertial>

    <collision name='hokuyo_collision'>
     <origin xyz="0.0 0 0" rpy=" 0 0 0"/>
      <geometry>
        <box size=".1 .1 .1"/>
      </geometry>
    </collision>

    <visual name='hokuyo_visual'>
      <origin xyz="0.0 0 0" rpy=" 0 0 0"/>
      <geometry>
        <mesh filename="package://my_robot/meshes/hokuyo.dae"/>
        <box size=".05 .05 .05"/>
      </geometry>
    </visual>

  </link>

  

  <joint type="fixed" name="hokuyo_joint">
    <origin xyz="0.35 0 0.08" rpy="0 0 0"/>
    <child link="hokuyo"/>
    <parent link="chassis"/>
    <axis xyz="0 1 0" rpy="0 0 0"/>
    <limit effort="10000" velocity="1000"/>
    <dynamics damping="1.0" friction="1.0"/>
  </joint>
  

</robot>
